2024-06-22 23:01:55,841:INFO:Waiting for 30 seconds before executing scripts...
2024-06-22 23:02:25,841:INFO:Running script: /home/pi/Python/Scripts/iss.py
2024-06-22 23:02:55,842:WARNING:/home/pi/Python/Scripts/iss.py ran for 30 seconds without errors.
2024-06-22 23:02:55,842:INFO:Running script: /home/pi/Python/Scripts/discord_bot.py
2024-06-22 23:03:25,843:WARNING:/home/pi/Python/Scripts/discord_bot.py ran for 30 seconds without errors.
2024-06-22 23:03:25,843:INFO:Preparing to connect to SMTP server...
2024-06-22 23:03:25,843:INFO:SMTP server: smtp.gmail.com
2024-06-22 23:03:25,843:INFO:SMTP port: 587
2024-06-22 23:03:25,843:INFO:Sender email: saeijou@gmail.com
2024-06-22 23:03:25,843:INFO:Receiver email: stephan.juchatz@googlemail.com
2024-06-22 23:03:25,843:INFO:Setting socket default timeout...
2024-06-22 23:35:46,693:INFO:Waiting for 30 seconds before executing scripts...
2024-06-22 23:36:16,697:INFO:Running script: /home/pi/Python/Scripts/iss.py
2024-06-22 23:36:46,700:WARNING:/home/pi/Python/Scripts/iss.py ran for 30 seconds without errors.
2024-06-22 23:36:46,700:INFO:Running script: /home/pi/Python/Scripts/discord_bot.py
2024-06-22 23:37:16,701:WARNING:/home/pi/Python/Scripts/discord_bot.py ran for 30 seconds without errors.
2024-06-22 23:37:16,701:INFO:Preparing to connect to SMTP server...
2024-06-22 23:37:16,701:INFO:SMTP server: smtp.gmail.com
2024-06-22 23:37:16,701:INFO:SMTP port: 587
2024-06-22 23:37:16,701:INFO:Sender email: saeijou@gmail.com
2024-06-22 23:37:16,701:INFO:Receiver email: stephan.juchatz@googlemail.com
2024-06-22 23:37:16,701:INFO:Setting socket default timeout...
2024-06-22 23:39:09,855:INFO:Waiting for 30 seconds before executing scripts...
2024-06-22 23:39:39,866:INFO:Running script: /home/pi/Python/Scripts/iss.py
2024-06-22 23:40:09,867:WARNING:/home/pi/Python/Scripts/iss.py ran for 30 seconds without errors.
2024-06-22 23:40:09,867:INFO:Running script: /home/pi/Python/Scripts/discord_bot.py
2024-06-22 23:40:39,867:WARNING:/home/pi/Python/Scripts/discord_bot.py ran for 30 seconds without errors.
2024-06-22 23:40:39,868:INFO:Preparing to connect to SMTP server...
2024-06-22 23:40:39,868:INFO:SMTP server: smtp.gmail.com
2024-06-22 23:40:39,868:INFO:SMTP port: 587
2024-06-22 23:40:39,868:INFO:Sender email: saeijou@gmail.com
2024-06-22 23:40:39,868:INFO:Receiver email: stephan.juchatz@googlemail.com
2024-06-22 23:40:39,868:INFO:Setting socket default timeout...
2024-06-22 23:44:39,818:INFO:Waiting for 30 seconds before executing scripts...
2024-06-22 23:45:09,819:INFO:Running script: /home/pi/Python/Scripts/iss.py
2024-06-22 23:45:17,862:ERROR:/home/pi/Python/Scripts/iss.py encountered an error with return code 1.
Error:
Traceback (most recent call last):
  File "/usr/lib/python3/dist-packages/urllib3/connection.py", line 174, in _new_conn
    conn = connection.create_connection(
           ^^^^^^^^^^^^^^^^^^^^^^^^^^^^^
  File "/usr/lib/python3/dist-packages/urllib3/util/connection.py", line 73, in create_connection
    for res in socket.getaddrinfo(host, port, family, socket.SOCK_STREAM):
               ^^^^^^^^^^^^^^^^^^^^^^^^^^^^^^^^^^^^^^^^^^^^^^^^^^^^^^^^^^
  File "/usr/lib/python3.11/socket.py", line 962, in getaddrinfo
    for res in _socket.getaddrinfo(host, port, family, type, proto, flags):
               ^^^^^^^^^^^^^^^^^^^^^^^^^^^^^^^^^^^^^^^^^^^^^^^^^^^^^^^^^^^
socket.gaierror: [Errno -3] Temporary failure in name resolution

During handling of the above exception, another exception occurred:

Traceback (most recent call last):
  File "/usr/lib/python3/dist-packages/urllib3/connectionpool.py", line 704, in urlopen
    httplib_response = self._make_request(
                       ^^^^^^^^^^^^^^^^^^^
  File "/usr/lib/python3/dist-packages/urllib3/connectionpool.py", line 399, in _make_request
    conn.request(method, url, **httplib_request_kw)
  File "/usr/lib/python3/dist-packages/urllib3/connection.py", line 239, in request
    super(HTTPConnection, self).request(method, url, body=body, headers=headers)
  File "/usr/lib/python3.11/http/client.py", line 1282, in request
    self._send_request(method, url, body, headers, encode_chunked)
  File "/usr/lib/python3.11/http/client.py", line 1328, in _send_request
    self.endheaders(body, encode_chunked=encode_chunked)
  File "/usr/lib/python3.11/http/client.py", line 1277, in endheaders
    self._send_output(message_body, encode_chunked=encode_chunked)
  File "/usr/lib/python3.11/http/client.py", line 1037, in _send_output
    self.send(msg)
  File "/usr/lib/python3.11/http/client.py", line 975, in send
    self.connect()
  File "/usr/lib/python3/dist-packages/urllib3/connection.py", line 205, in connect
    conn = self._new_conn()
           ^^^^^^^^^^^^^^^^
  File "/usr/lib/python3/dist-packages/urllib3/connection.py", line 186, in _new_conn
    raise NewConnectionError(
urllib3.exceptions.NewConnectionError: <urllib3.connection.HTTPConnection object at 0x7fff20b7e4d0>: Failed to establish a new connection: [Errno -3] Temporary failure in name resolution

During handling of the above exception, another exception occurred:

Traceback (most recent call last):
  File "/usr/lib/python3/dist-packages/requests/adapters.py", line 489, in send
    resp = conn.urlopen(
           ^^^^^^^^^^^^^
  File "/usr/lib/python3/dist-packages/urllib3/connectionpool.py", line 788, in urlopen
    retries = retries.increment(
              ^^^^^^^^^^^^^^^^^^
  File "/usr/lib/python3/dist-packages/urllib3/util/retry.py", line 592, in increment
    raise MaxRetryError(_pool, url, error or ResponseError(cause))
urllib3.exceptions.MaxRetryError: HTTPConnectionPool(host='api.open-notify.org', port=80): Max retries exceeded with url: /iss-now.json (Caused by NewConnectionError('<urllib3.connection.HTTPConnection object at 0x7fff20b7e4d0>: Failed to establish a new connection: [Errno -3] Temporary failure in name resolution'))

During handling of the above exception, another exception occurred:

Traceback (most recent call last):
  File "/home/pi/Python/Scripts/iss.py", line 13, in <module>
    response = requests.get(url="http://api.open-notify.org/iss-now.json")
               ^^^^^^^^^^^^^^^^^^^^^^^^^^^^^^^^^^^^^^^^^^^^^^^^^^^^^^^^^^^
  File "/usr/lib/python3/dist-packages/requests/api.py", line 73, in get
    return request("get", url, params=params, **kwargs)
           ^^^^^^^^^^^^^^^^^^^^^^^^^^^^^^^^^^^^^^^^^^^^
  File "/usr/lib/python3/dist-packages/requests/api.py", line 59, in request
    return session.request(method=method, url=url, **kwargs)
           ^^^^^^^^^^^^^^^^^^^^^^^^^^^^^^^^^^^^^^^^^^^^^^^^^
  File "/usr/lib/python3/dist-packages/requests/sessions.py", line 587, in request
    resp = self.send(prep, **send_kwargs)
           ^^^^^^^^^^^^^^^^^^^^^^^^^^^^^^
  File "/usr/lib/python3/dist-packages/requests/sessions.py", line 701, in send
    r = adapter.send(request, **kwargs)
        ^^^^^^^^^^^^^^^^^^^^^^^^^^^^^^^
  File "/usr/lib/python3/dist-packages/requests/adapters.py", line 565, in send
    raise ConnectionError(e, request=request)
requests.exceptions.ConnectionError: HTTPConnectionPool(host='api.open-notify.org', port=80): Max retries exceeded with url: /iss-now.json (Caused by NewConnectionError('<urllib3.connection.HTTPConnection object at 0x7fff20b7e4d0>: Failed to establish a new connection: [Errno -3] Temporary failure in name resolution'))

2024-06-22 23:45:17,862:INFO:Running script: /home/pi/Python/Scripts/discord_bot.py
2024-06-22 23:45:27,882:ERROR:/home/pi/Python/Scripts/discord_bot.py encountered an error with return code 1.
Error:
Traceback (most recent call last):
  File "/usr/lib/python3/dist-packages/aiohttp/connector.py", line 1152, in _create_direct_connection
    hosts = await asyncio.shield(host_resolved)
            ^^^^^^^^^^^^^^^^^^^^^^^^^^^^^^^^^^^
  File "/usr/lib/python3/dist-packages/aiohttp/connector.py", line 874, in _resolve_host
    addrs = await self._resolver.resolve(host, port, family=self._family)
            ^^^^^^^^^^^^^^^^^^^^^^^^^^^^^^^^^^^^^^^^^^^^^^^^^^^^^^^^^^^^^
  File "/usr/lib/python3/dist-packages/aiohttp/resolver.py", line 33, in resolve
    infos = await self._loop.getaddrinfo(
            ^^^^^^^^^^^^^^^^^^^^^^^^^^^^^
  File "/usr/lib/python3.11/asyncio/base_events.py", line 867, in getaddrinfo
    return await self.run_in_executor(
           ^^^^^^^^^^^^^^^^^^^^^^^^^^^
  File "/usr/lib/python3.11/concurrent/futures/thread.py", line 58, in run
    result = self.fn(*self.args, **self.kwargs)
             ^^^^^^^^^^^^^^^^^^^^^^^^^^^^^^^^^^
  File "/usr/lib/python3.11/socket.py", line 962, in getaddrinfo
    for res in _socket.getaddrinfo(host, port, family, type, proto, flags):
               ^^^^^^^^^^^^^^^^^^^^^^^^^^^^^^^^^^^^^^^^^^^^^^^^^^^^^^^^^^^
socket.gaierror: [Errno -3] Temporary failure in name resolution

The above exception was the direct cause of the following exception:

Traceback (most recent call last):
  File "/home/pi/Python/Scripts/discord_bot.py", line 58, in <module>
    asyncio.run(main())
  File "/usr/lib/python3.11/asyncio/runners.py", line 190, in run
    return runner.run(main)
           ^^^^^^^^^^^^^^^^
  File "/usr/lib/python3.11/asyncio/runners.py", line 118, in run
    return self._loop.run_until_complete(task)
           ^^^^^^^^^^^^^^^^^^^^^^^^^^^^^^^^^^^
  File "/usr/lib/python3.11/asyncio/base_events.py", line 653, in run_until_complete
    return future.result()
           ^^^^^^^^^^^^^^^
  File "/home/pi/Python/Scripts/discord_bot.py", line 55, in main
    await bot.start(TOKEN)
  File "/usr/lib/python3/dist-packages/discord/client.py", line 777, in start
    await self.login(token)
  File "/usr/lib/python3/dist-packages/discord/client.py", line 612, in login
    data = await self.http.static_login(token)
           ^^^^^^^^^^^^^^^^^^^^^^^^^^^^^^^^^^^
  File "/usr/lib/python3/dist-packages/discord/http.py", line 801, in static_login
    data = await self.request(Route('GET', '/users/@me'))
           ^^^^^^^^^^^^^^^^^^^^^^^^^^^^^^^^^^^^^^^^^^^^^^
  File "/usr/lib/python3/dist-packages/discord/http.py", line 624, in request
    async with self.__session.request(method, url, **kwargs) as response:
  File "/usr/lib/python3/dist-packages/aiohttp/client.py", line 1141, in __aenter__
    self._resp = await self._coro
                 ^^^^^^^^^^^^^^^^
  File "/usr/lib/python3/dist-packages/aiohttp/client.py", line 536, in _request
    conn = await self._connector.connect(
           ^^^^^^^^^^^^^^^^^^^^^^^^^^^^^^
  File "/usr/lib/python3/dist-packages/aiohttp/connector.py", line 540, in connect
    proto = await self._create_connection(req, traces, timeout)
            ^^^^^^^^^^^^^^^^^^^^^^^^^^^^^^^^^^^^^^^^^^^^^^^^^^^
  File "/usr/lib/python3/dist-packages/aiohttp/connector.py", line 901, in _create_connection
    _, proto = await self._create_direct_connection(req, traces, timeout)
               ^^^^^^^^^^^^^^^^^^^^^^^^^^^^^^^^^^^^^^^^^^^^^^^^^^^^^^^^^^
  File "/usr/lib/python3/dist-packages/aiohttp/connector.py", line 1166, in _create_direct_connection
    raise ClientConnectorError(req.connection_key, exc) from exc
aiohttp.client_exceptions.ClientConnectorError: Cannot connect to host discord.com:443 ssl:default [Temporary failure in name resolution]

2024-06-22 23:45:27,883:INFO:Preparing to connect to SMTP server...
2024-06-22 23:45:27,883:INFO:SMTP server: smtp.gmail.com
2024-06-22 23:45:27,883:INFO:SMTP port: 587
2024-06-22 23:45:27,883:INFO:Sender email: saeijou@gmail.com
2024-06-22 23:45:27,883:INFO:Receiver email: stephan.juchatz@googlemail.com
2024-06-22 23:45:27,883:INFO:Setting socket default timeout...
